2025-10-21 01:08:18 EEST | ERROR    | Error checking AP signal 4:
Traceback (most recent call last):
  File "D:\bot\Новая папка\BinanceBotAssistant\BinanceBotAssistant\venv\Lib\site-packages\aiohttp\client.py", line 770, in _request
    resp = await handler(req)
           ^^^^^^^^^^^^^^^^^^
  File "D:\bot\Новая папка\BinanceBotAssistant\BinanceBotAssistant\venv\Lib\site-packages\aiohttp\client.py", line 725, in _connect_and_send_request
    conn = await self._connector.connect(
           ^^^^^^^^^^^^^^^^^^^^^^^^^^^^^^
  File "D:\bot\Новая папка\BinanceBotAssistant\BinanceBotAssistant\venv\Lib\site-packages\aiohttp\connector.py", line 642, in connect
    proto = await self._create_connection(req, traces, timeout)
            ^^^^^^^^^^^^^^^^^^^^^^^^^^^^^^^^^^^^^^^^^^^^^^^^^^^
  File "D:\bot\Новая папка\BinanceBotAssistant\BinanceBotAssistant\venv\Lib\site-packages\aiohttp\connector.py", line 1209, in _create_connection
    _, proto = await self._create_direct_connection(req, traces, timeout)
               ^^^^^^^^^^^^^^^^^^^^^^^^^^^^^^^^^^^^^^^^^^^^^^^^^^^^^^^^^^
  File "D:\bot\Новая папка\BinanceBotAssistant\BinanceBotAssistant\venv\Lib\site-packages\aiohttp\connector.py", line 1550, in _create_direct_connection
    transp, proto = await self._wrap_create_connection(
                    ^^^^^^^^^^^^^^^^^^^^^^^^^^^^^^^^^^^
  File "D:\bot\Новая папка\BinanceBotAssistant\BinanceBotAssistant\venv\Lib\site-packages\aiohttp\connector.py", line 1283, in _wrap_create_connection
    return await self._loop.create_connection(*args, **kwargs, sock=sock)
           ^^^^^^^^^^^^^^^^^^^^^^^^^^^^^^^^^^^^^^^^^^^^^^^^^^^^^^^^^^^^^^
  File "C:\Users\User\AppData\Local\Programs\Python\Python312\Lib\asyncio\base_events.py", line 1148, in create_connection
    transport, protocol = await self._create_connection_transport(
                          ^^^^^^^^^^^^^^^^^^^^^^^^^^^^^^^^^^^^^^^^
  File "C:\Users\User\AppData\Local\Programs\Python\Python312\Lib\asyncio\base_events.py", line 1181, in _create_connection_transport
    await waiter
asyncio.exceptions.CancelledError

The above exception was the direct cause of the following exception:

Traceback (most recent call last):
  File "D:\bot\Новая папка\BinanceBotAssistant\BinanceBotAssistant\src\action_price\performance_tracker.py", line 91, in _check_signal
    price_data = await self.binance_client.get_mark_price(symbol_str)
                 ^^^^^^^^^^^^^^^^^^^^^^^^^^^^^^^^^^^^^^^^^^^^^^^^^^^^
  File "D:\bot\Новая папка\BinanceBotAssistant\BinanceBotAssistant\src\binance\client.py", line 329, in get_mark_price
    return await self._request('GET', '/fapi/v1/premiumIndex', params=params, weight=1)
           ^^^^^^^^^^^^^^^^^^^^^^^^^^^^^^^^^^^^^^^^^^^^^^^^^^^^^^^^^^^^^^^^^^^^^^^^^^^^
  File "D:\bot\Новая папка\BinanceBotAssistant\BinanceBotAssistant\src\binance\client.py", line 104, in _request
    return await self.rate_limiter.execute_with_backoff(_do_request, weight=weight)
           ^^^^^^^^^^^^^^^^^^^^^^^^^^^^^^^^^^^^^^^^^^^^^^^^^^^^^^^^^^^^^^^^^^^^^^^^
  File "D:\bot\Новая папка\BinanceBotAssistant\BinanceBotAssistant\src\utils\rate_limiter.py", line 100, in execute_with_backoff
    result = await func(*args, **kwargs)
             ^^^^^^^^^^^^^^^^^^^^^^^^^^^
  File "D:\bot\Новая папка\BinanceBotAssistant\BinanceBotAssistant\src\binance\client.py", line 85, in _do_request
    async with self.session.request(method, url, params=params, headers=headers) as response:
               ^^^^^^^^^^^^^^^^^^^^^^^^^^^^^^^^^^^^^^^^^^^^^^^^^^^^^^^^^^^^^^^^^
  File "D:\bot\Новая папка\BinanceBotAssistant\BinanceBotAssistant\venv\Lib\site-packages\aiohttp\client.py", line 1488, in __aenter__
    self._resp: _RetType = await self._coro
                           ^^^^^^^^^^^^^^^^
  File "D:\bot\Новая папка\BinanceBotAssistant\BinanceBotAssistant\venv\Lib\site-packages\aiohttp\client.py", line 622, in _request
    with timer:
         ^^^^^
  File "D:\bot\Новая папка\BinanceBotAssistant\BinanceBotAssistant\venv\Lib\site-packages\aiohttp\helpers.py", line 685, in __exit__
    raise asyncio.TimeoutError from exc_val
TimeoutError