2025-10-20 01:04:38 EEST | ERROR    | trading_bot | Error fetching orderbook for KAITOUSDT:
2025-10-20 01:05:08 EEST | WARNING  | trading_bot | Error downloading RUNEUSDT 15m on 2025-10-19: TimeoutError. Retry 1/3 in 2s
2025-10-20 01:05:08 EEST | WARNING  | trading_bot | Error downloading SUSHIUSDT 15m on 2025-10-19: TimeoutError. Retry 1/3 in 2s
2025-10-20 01:05:08 EEST | WARNING  | trading_bot | ⏳ Previous signal check still running, skipping this cycle
2025-10-20 01:05:08 EEST | ERROR    | trading_bot | Error updating symbols:
Traceback (most recent call last):
  File "D:\bot\Новая папка\BinanceBotAssistant\BinanceBotAssistant\venv\Lib\site-packages\aiohttp\client_reqrep.py", line 541, in start
    message, payload = await protocol.read()  # type: ignore[union-attr]
                       ^^^^^^^^^^^^^^^^^^^^^
  File "D:\bot\Новая папка\BinanceBotAssistant\BinanceBotAssistant\venv\Lib\site-packages\aiohttp\streams.py", line 680, in read
    await self._waiter
asyncio.exceptions.CancelledError

The above exception was the direct cause of the following exception:

Traceback (most recent call last):
  File "D:\bot\Новая папка\BinanceBotAssistant\BinanceBotAssistant\main.py", line 1236, in _update_symbols_task
    new_symbols = await self._fetch_symbols_by_volume()
                  ^^^^^^^^^^^^^^^^^^^^^^^^^^^^^^^^^^^^^
  File "D:\bot\Новая папка\BinanceBotAssistant\BinanceBotAssistant\main.py", line 164, in _fetch_symbols_by_volume
    ticker_data = await self.client.get_24h_ticker()
                  ^^^^^^^^^^^^^^^^^^^^^^^^^^^^^^^^^^
  File "D:\bot\Новая папка\BinanceBotAssistant\BinanceBotAssistant\src\binance\client.py", line 320, in get_24h_ticker
    return await self._request('GET', '/fapi/v1/ticker/24hr', params=params, weight=weight)
           ^^^^^^^^^^^^^^^^^^^^^^^^^^^^^^^^^^^^^^^^^^^^^^^^^^^^^^^^^^^^^^^^^^^^^^^^^^^^^^^^
  File "D:\bot\Новая папка\BinanceBotAssistant\BinanceBotAssistant\src\binance\client.py", line 100, in _request
    return await self.rate_limiter.execute_with_backoff(_do_request, weight=weight)
           ^^^^^^^^^^^^^^^^^^^^^^^^^^^^^^^^^^^^^^^^^^^^^^^^^^^^^^^^^^^^^^^^^^^^^^^^
  File "D:\bot\Новая папка\BinanceBotAssistant\BinanceBotAssistant\src\utils\rate_limiter.py", line 100, in execute_with_backoff
    result = await func(*args, **kwargs)
             ^^^^^^^^^^^^^^^^^^^^^^^^^^^
  File "D:\bot\Новая папка\BinanceBotAssistant\BinanceBotAssistant\src\binance\client.py", line 81, in _do_request
    async with self.session.request(method, url, params=params, headers=headers) as response:
               ^^^^^^^^^^^^^^^^^^^^^^^^^^^^^^^^^^^^^^^^^^^^^^^^^^^^^^^^^^^^^^^^^
  File "D:\bot\Новая папка\BinanceBotAssistant\BinanceBotAssistant\venv\Lib\site-packages\aiohttp\client.py", line 1488, in __aenter__
    self._resp: _RetType = await self._coro
                           ^^^^^^^^^^^^^^^^
  File "D:\bot\Новая папка\BinanceBotAssistant\BinanceBotAssistant\venv\Lib\site-packages\aiohttp\client.py", line 770, in _request
    resp = await handler(req)
           ^^^^^^^^^^^^^^^^^^
  File "D:\bot\Новая папка\BinanceBotAssistant\BinanceBotAssistant\venv\Lib\site-packages\aiohttp\client.py", line 748, in _connect_and_send_request
    await resp.start(conn)
  File "D:\bot\Новая папка\BinanceBotAssistant\BinanceBotAssistant\venv\Lib\site-packages\aiohttp\client_reqrep.py", line 536, in start
    with self._timer:
         ^^^^^^^^^^^
  File "D:\bot\Новая папка\BinanceBotAssistant\BinanceBotAssistant\venv\Lib\site-packages\aiohttp\helpers.py", line 685, in __exit__
    raise asyncio.TimeoutError from exc_val
TimeoutError
