Exception happened while polling for updates.
Traceback (most recent call last):
  File "D:\bot\Новая папка\BinanceBotAssistant\BinanceBotAssistant\venv\Lib\site-packages\httpx\_transports\default.py", line 101, in map_httpcore_exceptions
    yield
  File "D:\bot\Новая папка\BinanceBotAssistant\BinanceBotAssistant\venv\Lib\site-packages\httpx\_transports\default.py", line 394, in handle_async_request
    resp = await self._pool.handle_async_request(req)
           ^^^^^^^^^^^^^^^^^^^^^^^^^^^^^^^^^^^^^^^^^^
  File "D:\bot\Новая папка\BinanceBotAssistant\BinanceBotAssistant\venv\Lib\site-packages\httpcore\_async\connection_pool.py", line 256, in handle_async_request
    raise exc from None
  File "D:\bot\Новая папка\BinanceBotAssistant\BinanceBotAssistant\venv\Lib\site-packages\httpcore\_async\connection_pool.py", line 236, in handle_async_request
    response = await connection.handle_async_request(
               ^^^^^^^^^^^^^^^^^^^^^^^^^^^^^^^^^^^^^^
  File "D:\bot\Новая папка\BinanceBotAssistant\BinanceBotAssistant\venv\Lib\site-packages\httpcore\_async\connection.py", line 103, in handle_async_request
    return await self._connection.handle_async_request(request)
           ^^^^^^^^^^^^^^^^^^^^^^^^^^^^^^^^^^^^^^^^^^^^^^^^^^^^
  File "D:\bot\Новая папка\BinanceBotAssistant\BinanceBotAssistant\venv\Lib\site-packages\httpcore\_async\http11.py", line 136, in handle_async_request
    raise exc
  File "D:\bot\Новая папка\BinanceBotAssistant\BinanceBotAssistant\venv\Lib\site-packages\httpcore\_async\http11.py", line 106, in handle_async_request
    ) = await self._receive_response_headers(**kwargs)
        ^^^^^^^^^^^^^^^^^^^^^^^^^^^^^^^^^^^^^^^^^^^^^^
  File "D:\bot\Новая папка\BinanceBotAssistant\BinanceBotAssistant\venv\Lib\site-packages\httpcore\_async\http11.py", line 177, in _receive_response_headers
    event = await self._receive_event(timeout=timeout)
            ^^^^^^^^^^^^^^^^^^^^^^^^^^^^^^^^^^^^^^^^^^
  File "D:\bot\Новая папка\BinanceBotAssistant\BinanceBotAssistant\venv\Lib\site-packages\httpcore\_async\http11.py", line 217, in _receive_event
    data = await self._network_stream.read(
           ^^^^^^^^^^^^^^^^^^^^^^^^^^^^^^^^
  File "D:\bot\Новая папка\BinanceBotAssistant\BinanceBotAssistant\venv\Lib\site-packages\httpcore\_backends\anyio.py", line 32, in read
    with map_exceptions(exc_map):
         ^^^^^^^^^^^^^^^^^^^^^^^
  File "C:\Users\User\AppData\Local\Programs\Python\Python312\Lib\contextlib.py", line 158, in __exit__
    self.gen.throw(value)
  File "D:\bot\Новая папка\BinanceBotAssistant\BinanceBotAssistant\venv\Lib\site-packages\httpcore\_exceptions.py", line 14, in map_exceptions
    raise to_exc(exc) from exc
httpcore.ReadError

The above exception was the direct cause of the following exception:

Traceback (most recent call last):
  File "D:\bot\Новая папка\BinanceBotAssistant\BinanceBotAssistant\venv\Lib\site-packages\telegram\request\_httpxrequest.py", line 279, in do_request
    res = await self._client.request(
          ^^^^^^^^^^^^^^^^^^^^^^^^^^^
  File "D:\bot\Новая папка\BinanceBotAssistant\BinanceBotAssistant\venv\Lib\site-packages\httpx\_client.py", line 1540, in request
    return await self.send(request, auth=auth, follow_redirects=follow_redirects)
           ^^^^^^^^^^^^^^^^^^^^^^^^^^^^^^^^^^^^^^^^^^^^^^^^^^^^^^^^^^^^^^^^^^^^^^
  File "D:\bot\Новая папка\BinanceBotAssistant\BinanceBotAssistant\venv\Lib\site-packages\httpx\_client.py", line 1629, in send
    response = await self._send_handling_auth(
               ^^^^^^^^^^^^^^^^^^^^^^^^^^^^^^^
  File "D:\bot\Новая папка\BinanceBotAssistant\BinanceBotAssistant\venv\Lib\site-packages\httpx\_client.py", line 1657, in _send_handling_auth
    response = await self._send_handling_redirects(
               ^^^^^^^^^^^^^^^^^^^^^^^^^^^^^^^^^^^^
  File "D:\bot\Новая папка\BinanceBotAssistant\BinanceBotAssistant\venv\Lib\site-packages\httpx\_client.py", line 1694, in _send_handling_redirects
    response = await self._send_single_request(request)
               ^^^^^^^^^^^^^^^^^^^^^^^^^^^^^^^^^^^^^^^^
  File "D:\bot\Новая папка\BinanceBotAssistant\BinanceBotAssistant\venv\Lib\site-packages\httpx\_client.py", line 1730, in _send_single_request
    response = await transport.handle_async_request(request)
               ^^^^^^^^^^^^^^^^^^^^^^^^^^^^^^^^^^^^^^^^^^^^^
  File "D:\bot\Новая папка\BinanceBotAssistant\BinanceBotAssistant\venv\Lib\site-packages\httpx\_transports\default.py", line 393, in handle_async_request
    with map_httpcore_exceptions():
         ^^^^^^^^^^^^^^^^^^^^^^^^^
  File "C:\Users\User\AppData\Local\Programs\Python\Python312\Lib\contextlib.py", line 158, in __exit__
    self.gen.throw(value)
  File "D:\bot\Новая папка\BinanceBotAssistant\BinanceBotAssistant\venv\Lib\site-packages\httpx\_transports\default.py", line 118, in map_httpcore_exceptions
    raise mapped_exc(message) from exc
httpx.ReadError

The above exception was the direct cause of the following exception:

Traceback (most recent call last):
  File "D:\bot\Новая папка\BinanceBotAssistant\BinanceBotAssistant\venv\Lib\site-packages\telegram\ext\_utils\networkloop.py", line 134, in network_retry_loop
    await do_action()
  File "D:\bot\Новая папка\BinanceBotAssistant\BinanceBotAssistant\venv\Lib\site-packages\telegram\ext\_utils\networkloop.py", line 127, in do_action
    action_cb_task.result()
  File "D:\bot\Новая папка\BinanceBotAssistant\BinanceBotAssistant\venv\Lib\site-packages\telegram\ext\_updater.py", line 340, in polling_action_cb
    updates = await self.bot.get_updates(
              ^^^^^^^^^^^^^^^^^^^^^^^^^^^
  File "D:\bot\Новая папка\BinanceBotAssistant\BinanceBotAssistant\venv\Lib\site-packages\telegram\ext\_extbot.py", line 676, in get_updates
    updates = await super().get_updates(
              ^^^^^^^^^^^^^^^^^^^^^^^^^^
  File "D:\bot\Новая папка\BinanceBotAssistant\BinanceBotAssistant\venv\Lib\site-packages\telegram\_bot.py", line 4780, in get_updates
    await self._post(
  File "D:\bot\Новая папка\BinanceBotAssistant\BinanceBotAssistant\venv\Lib\site-packages\telegram\_bot.py", line 703, in _post
    return await self._do_post(
           ^^^^^^^^^^^^^^^^^^^^
  File "D:\bot\Новая папка\BinanceBotAssistant\BinanceBotAssistant\venv\Lib\site-packages\telegram\ext\_extbot.py", line 372, in _do_post
    return await super()._do_post(
           ^^^^^^^^^^^^^^^^^^^^^^^
  File "D:\bot\Новая папка\BinanceBotAssistant\BinanceBotAssistant\venv\Lib\site-packages\telegram\_bot.py", line 732, in _do_post
    result = await request.post(
             ^^^^^^^^^^^^^^^^^^^
  File "D:\bot\Новая папка\BinanceBotAssistant\BinanceBotAssistant\venv\Lib\site-packages\telegram\request\_baserequest.py", line 198, in post
    result = await self._request_wrapper(
             ^^^^^^^^^^^^^^^^^^^^^^^^^^^^
  File "D:\bot\Новая папка\BinanceBotAssistant\BinanceBotAssistant\venv\Lib\site-packages\telegram\request\_baserequest.py", line 305, in _request_wrapper
    code, payload = await self.do_request(
                    ^^^^^^^^^^^^^^^^^^^^^^
  File "D:\bot\Новая папка\BinanceBotAssistant\BinanceBotAssistant\venv\Lib\site-packages\telegram\request\_httpxrequest.py", line 303, in do_request
    raise NetworkError(f"httpx.{err.__class__.__name__}: {err}") from err
telegram.error.NetworkError: httpx.ReadError: