No error handlers are registered, logging exception.
Traceback (most recent call last):
  File "/home/runner/workspace/.pythonlibs/lib/python3.12/site-packages/telegram/ext/_application.py", line 1315, in process_update
    await coroutine
  File "/home/runner/workspace/.pythonlibs/lib/python3.12/site-packages/telegram/ext/_handlers/basehandler.py", line 159, in handle_update
    return await self.callback(update, context)
           ^^^^^^^^^^^^^^^^^^^^^^^^^^^^^^^^^^^^
  File "/home/runner/workspace/src/telegram/bot.py", line 76, in cmd_start
    await update.message.reply_text(welcome_text, parse_mode='Markdown')
  File "/home/runner/workspace/.pythonlibs/lib/python3.12/site-packages/telegram/_message.py", line 2060, in reply_text
    return await self.get_bot().send_message(
           ^^^^^^^^^^^^^^^^^^^^^^^^^^^^^^^^^^
  File "/home/runner/workspace/.pythonlibs/lib/python3.12/site-packages/telegram/ext/_extbot.py", line 3107, in send_message
    return await super().send_message(
           ^^^^^^^^^^^^^^^^^^^^^^^^^^^
  File "/home/runner/workspace/.pythonlibs/lib/python3.12/site-packages/telegram/_bot.py", line 1118, in send_message
    return await self._send_message(
           ^^^^^^^^^^^^^^^^^^^^^^^^^
  File "/home/runner/workspace/.pythonlibs/lib/python3.12/site-packages/telegram/ext/_extbot.py", line 634, in _send_message
    result = await super()._send_message(
             ^^^^^^^^^^^^^^^^^^^^^^^^^^^^
  File "/home/runner/workspace/.pythonlibs/lib/python3.12/site-packages/telegram/_bot.py", line 819, in _send_message
    result = await self._post(
             ^^^^^^^^^^^^^^^^^
  File "/home/runner/workspace/.pythonlibs/lib/python3.12/site-packages/telegram/_bot.py", line 703, in _post
    return await self._do_post(
           ^^^^^^^^^^^^^^^^^^^^
  File "/home/runner/workspace/.pythonlibs/lib/python3.12/site-packages/telegram/ext/_extbot.py", line 372, in _do_post
    return await super()._do_post(
           ^^^^^^^^^^^^^^^^^^^^^^^
  File "/home/runner/workspace/.pythonlibs/lib/python3.12/site-packages/telegram/_bot.py", line 732, in _do_post
    result = await request.post(
             ^^^^^^^^^^^^^^^^^^^
  File "/home/runner/workspace/.pythonlibs/lib/python3.12/site-packages/telegram/request/_baserequest.py", line 198, in post
    result = await self._request_wrapper(
             ^^^^^^^^^^^^^^^^^^^^^^^^^^^^
  File "/home/runner/workspace/.pythonlibs/lib/python3.12/site-packages/telegram/request/_baserequest.py", line 375, in _request_wrapper
    raise exception
telegram.error.BadRequest: Can't parse entities: can't find end of the entity starting at byte offset 307