0:00+00:00 to 2025-10-16 18:28:58.529258+00:00 (1 days)
2025-10-16 21:51:26 EEST | ERROR    | Error checking AP signal 33:
Traceback (most recent call last):
  File "D:\bot\Новая папка\BinanceBotAssistant\BinanceBotAssistant\venv\Lib\site-packages\aiohttp\client_reqrep.py", line 541, in start
    message, payload = await protocol.read()  # type: ignore[union-attr]
                       ^^^^^^^^^^^^^^^^^^^^^
  File "D:\bot\Новая папка\BinanceBotAssistant\BinanceBotAssistant\venv\Lib\site-packages\aiohttp\streams.py", line 680, in read
    await self._waiter
asyncio.exceptions.CancelledError

The above exception was the direct cause of the following exception:

Traceback (most recent call last):
  File "D:\bot\Новая папка\BinanceBotAssistant\BinanceBotAssistant\src\action_price\performance_tracker.py", line 91, in _check_signal
    price_data = await self.binance_client.get_mark_price(symbol_str)
                 ^^^^^^^^^^^^^^^^^^^^^^^^^^^^^^^^^^^^^^^^^^^^^^^^^^^^
  File "D:\bot\Новая папка\BinanceBotAssistant\BinanceBotAssistant\src\binance\client.py", line 316, in get_mark_price
    return await self._request('GET', '/fapi/v1/premiumIndex', params=params, weight=1)
           ^^^^^^^^^^^^^^^^^^^^^^^^^^^^^^^^^^^^^^^^^^^^^^^^^^^^^^^^^^^^^^^^^^^^^^^^^^^^
  File "D:\bot\Новая папка\BinanceBotAssistant\BinanceBotAssistant\src\binance\client.py", line 97, in _request
    return await self.rate_limiter.execute_with_backoff(_do_request, weight=weight)
           ^^^^^^^^^^^^^^^^^^^^^^^^^^^^^^^^^^^^^^^^^^^^^^^^^^^^^^^^^^^^^^^^^^^^^^^^
  File "D:\bot\Новая папка\BinanceBotAssistant\BinanceBotAssistant\src\utils\rate_limiter.py", line 100, in execute_with_backoff
    result = await func(*args, **kwargs)
             ^^^^^^^^^^^^^^^^^^^^^^^^^^^
  File "D:\bot\Новая папка\BinanceBotAssistant\BinanceBotAssistant\src\binance\client.py", line 78, in _do_request
    async with self.session.request(method, url, params=params, headers=headers) as response:
               ^^^^^^^^^^^^^^^^^^^^^^^^^^^^^^^^^^^^^^^^^^^^^^^^^^^^^^^^^^^^^^^^^
  File "D:\bot\Новая папка\BinanceBotAssistant\BinanceBotAssistant\venv\Lib\site-packages\aiohttp\client.py", line 1488, in __aenter__
    self._resp: _RetType = await self._coro
                           ^^^^^^^^^^^^^^^^
  File "D:\bot\Новая папка\BinanceBotAssistant\BinanceBotAssistant\venv\Lib\site-packages\aiohttp\client.py", line 770, in _request
    resp = await handler(req)
           ^^^^^^^^^^^^^^^^^^
  File "D:\bot\Новая папка\BinanceBotAssistant\BinanceBotAssistant\venv\Lib\site-packages\aiohttp\client.py", line 748, in _connect_and_send_request
    await resp.start(conn)
  File "D:\bot\Новая папка\BinanceBotAssistant\BinanceBotAssistant\venv\Lib\site-packages\aiohttp\client_reqrep.py", line 536, in start
    with self._timer:
         ^^^^^^^^^^^
  File "D:\bot\Новая папка\BinanceBotAssistant\BinanceBotAssistant\venv\Lib\site-packages\aiohttp\helpers.py", line 685, in __exit__
    raise asyncio.TimeoutError from exc_val
TimeoutError
2025-10-16 21:51:26 EEST | WARNING  | trading_bot | Error downloading SYRUPUSDT 15m on 2025-10-16: TimeoutError. Retry 1/3 in 2s
2025-10-16 21:51:28 EEST | WARNING  | trading_bot | Error downloading FUNUSDT 15m on 2025-08-04: TimeoutError. Retry 1/3 in 2s
Exception happened while polling for updates.
Traceback (most recent call last):
  File "D:\bot\Новая папка\BinanceBotAssistant\BinanceBotAssistant\venv\Lib\site-packages\httpx\_transports\default.py", line 101, in map_httpcore_exceptions
    yield
  File "D:\bot\Новая папка\BinanceBotAssistant\BinanceBotAssistant\venv\Lib\site-packages\httpx\_transports\default.py", line 394, in handle_async_request
    resp = await self._pool.handle_async_request(req)
           ^^^^^^^^^^^^^^^^^^^^^^^^^^^^^^^^^^^^^^^^^^
  File "D:\bot\Новая папка\BinanceBotAssistant\BinanceBotAssistant\venv\Lib\site-packages\httpcore\_async\connection_pool.py", line 256, in handle_async_request
    raise exc from None
  File "D:\bot\Новая папка\BinanceBotAssistant\BinanceBotAssistant\venv\Lib\site-packages\httpcore\_async\connection_pool.py", line 236, in handle_async_request
    response = await connection.handle_async_request(
               ^^^^^^^^^^^^^^^^^^^^^^^^^^^^^^^^^^^^^^
  File "D:\bot\Новая папка\BinanceBotAssistant\BinanceBotAssistant\venv\Lib\site-packages\httpcore\_async\connection.py", line 103, in handle_async_request
    return await self._connection.handle_async_request(request)
           ^^^^^^^^^^^^^^^^^^^^^^^^^^^^^^^^^^^^^^^^^^^^^^^^^^^^
  File "D:\bot\Новая папка\BinanceBotAssistant\BinanceBotAssistant\venv\Lib\site-packages\httpcore\_async\http11.py", line 136, in handle_async_request
    raise exc
  File "D:\bot\Новая папка\BinanceBotAssistant\BinanceBotAssistant\venv\Lib\site-packages\httpcore\_async\http11.py", line 106, in handle_async_request
    ) = await self._receive_response_headers(**kwargs)
        ^^^^^^^^^^^^^^^^^^^^^^^^^^^^^^^^^^^^^^^^^^^^^^
  File "D:\bot\Новая папка\BinanceBotAssistant\BinanceBotAssistant\venv\Lib\site-packages\httpcore\_async\http11.py", line 177, in _receive_response_headers
    event = await self._receive_event(timeout=timeout)
            ^^^^^^^^^^^^^^^^^^^^^^^^^^^^^^^^^^^^^^^^^^
  File "D:\bot\Новая папка\BinanceBotAssistant\BinanceBotAssistant\venv\Lib\site-packages\httpcore\_async\http11.py", line 217, in _receive_event
    data = await self._network_stream.read(
           ^^^^^^^^^^^^^^^^^^^^^^^^^^^^^^^^
  File "D:\bot\Новая папка\BinanceBotAssistant\BinanceBotAssistant\venv\Lib\site-packages\httpcore\_backends\anyio.py", line 32, in read
    with map_exceptions(exc_map):
         ^^^^^^^^^^^^^^^^^^^^^^^
  File "C:\Users\User\AppData\Local\Programs\Python\Python312\Lib\contextlib.py", line 158, in __exit__
    self.gen.throw(value)
  File "D:\bot\Новая папка\BinanceBotAssistant\BinanceBotAssistant\venv\Lib\site-packages\httpcore\_exceptions.py", line 14, in map_exceptions
    raise to_exc(exc) from exc
httpcore.ReadError

The above exception was the direct cause of the following exception:

Traceback (most recent call last):
  File "D:\bot\Новая папка\BinanceBotAssistant\BinanceBotAssistant\venv\Lib\site-packages\telegram\request\_httpxrequest.py", line 279, in do_request
    res = await self._client.request(
          ^^^^^^^^^^^^^^^^^^^^^^^^^^^
  File "D:\bot\Новая папка\BinanceBotAssistant\BinanceBotAssistant\venv\Lib\site-packages\httpx\_client.py", line 1540, in request
    return await self.send(request, auth=auth, follow_redirects=follow_redirects)
           ^^^^^^^^^^^^^^^^^^^^^^^^^^^^^^^^^^^^^^^^^^^^^^^^^^^^^^^^^^^^^^^^^^^^^^
  File "D:\bot\Новая папка\BinanceBotAssistant\BinanceBotAssistant\venv\Lib\site-packages\httpx\_client.py", line 1629, in send
    response = await self._send_handling_auth(
               ^^^^^^^^^^^^^^^^^^^^^^^^^^^^^^^
  File "D:\bot\Новая папка\BinanceBotAssistant\BinanceBotAssistant\venv\Lib\site-packages\httpx\_client.py", line 1657, in _send_handling_auth
    response = await self._send_handling_redirects(
               ^^^^^^^^^^^^^^^^^^^^^^^^^^^^^^^^^^^^
  File "D:\bot\Новая папка\BinanceBotAssistant\BinanceBotAssistant\venv\Lib\site-packages\httpx\_client.py", line 1694, in _send_handling_redirects
    response = await self._send_single_request(request)
               ^^^^^^^^^^^^^^^^^^^^^^^^^^^^^^^^^^^^^^^^
  File "D:\bot\Новая папка\BinanceBotAssistant\BinanceBotAssistant\venv\Lib\site-packages\httpx\_client.py", line 1730, in _send_single_request
    response = await transport.handle_async_request(request)
               ^^^^^^^^^^^^^^^^^^^^^^^^^^^^^^^^^^^^^^^^^^^^^
  File "D:\bot\Новая папка\BinanceBotAssistant\BinanceBotAssistant\venv\Lib\site-packages\httpx\_transports\default.py", line 393, in handle_async_request
    with map_httpcore_exceptions():
         ^^^^^^^^^^^^^^^^^^^^^^^^^
  File "C:\Users\User\AppData\Local\Programs\Python\Python312\Lib\contextlib.py", line 158, in __exit__
    self.gen.throw(value)
  File "D:\bot\Новая папка\BinanceBotAssistant\BinanceBotAssistant\venv\Lib\site-packages\httpx\_transports\default.py", line 118, in map_httpcore_exceptions
    raise mapped_exc(message) from exc
httpx.ReadError

The above exception was the direct cause of the following exception:

Traceback (most recent call last):
  File "D:\bot\Новая папка\BinanceBotAssistant\BinanceBotAssistant\venv\Lib\site-packages\telegram\ext\_utils\networkloop.py", line 134, in network_retry_loop
    await do_action()
  File "D:\bot\Новая папка\BinanceBotAssistant\BinanceBotAssistant\venv\Lib\site-packages\telegram\ext\_utils\networkloop.py", line 127, in do_action
    action_cb_task.result()
  File "D:\bot\Новая папка\BinanceBotAssistant\BinanceBotAssistant\venv\Lib\site-packages\telegram\ext\_updater.py", line 340, in polling_action_cb
    updates = await self.bot.get_updates(
              ^^^^^^^^^^^^^^^^^^^^^^^^^^^
  File "D:\bot\Новая папка\BinanceBotAssistant\BinanceBotAssistant\venv\Lib\site-packages\telegram\ext\_extbot.py", line 676, in get_updates
    updates = await super().get_updates(
              ^^^^^^^^^^^^^^^^^^^^^^^^^^
  File "D:\bot\Новая папка\BinanceBotAssistant\BinanceBotAssistant\venv\Lib\site-packages\telegram\_bot.py", line 4780, in get_updates
    await self._post(
  File "D:\bot\Новая папка\BinanceBotAssistant\BinanceBotAssistant\venv\Lib\site-packages\telegram\_bot.py", line 703, in _post
    return await self._do_post(
           ^^^^^^^^^^^^^^^^^^^^
  File "D:\bot\Новая папка\BinanceBotAssistant\BinanceBotAssistant\venv\Lib\site-packages\telegram\ext\_extbot.py", line 372, in _do_post
    return await super()._do_post(
           ^^^^^^^^^^^^^^^^^^^^^^^
  File "D:\bot\Новая папка\BinanceBotAssistant\BinanceBotAssistant\venv\Lib\site-packages\telegram\_bot.py", line 732, in _do_post
    result = await request.post(
             ^^^^^^^^^^^^^^^^^^^
  File "D:\bot\Новая папка\BinanceBotAssistant\BinanceBotAssistant\venv\Lib\site-packages\telegram\request\_baserequest.py", line 198, in post
    result = await self._request_wrapper(
             ^^^^^^^^^^^^^^^^^^^^^^^^^^^^
  File "D:\bot\Новая папка\BinanceBotAssistant\BinanceBotAssistant\venv\Lib\site-packages\telegram\request\_baserequest.py", line 305, in _request_wrapper
    code, payload = await self.do_request(
                    ^^^^^^^^^^^^^^^^^^^^^^
  File "D:\bot\Новая папка\BinanceBotAssistant\BinanceBotAssistant\venv\Lib\site-packages\telegram\request\_httpxrequest.py", line 303, in do_request
    raise NetworkError(f"httpx.{err.__class__.__name__}: {err}") from err
telegram.error.NetworkError: httpx.ReadError:


